Workbook
Name IMP_MOD: 'Implantación por tienda'!$A$8:$A$659
Name IMP_NT: 'Implantación por tienda'!$C$8:$C$659
Name IMP_TOT: 'Implantación por tienda'!$B$8:$B$659
Name REP_MOD: 'Reposición por tienda'!$A$8:$A$659
Name REP_TOT: 'Reposición por tienda'!$B$8:$B$659
Name TIENDAS: 'Implantación por tienda'!$K$4

Sheet MASTER por modelo
A1: KOROSHI · MASTER OI 26/27 · por modelo
A2: Una fila por modelo del packing list (sin color). Datos PL desde la hoja «Detalle por artículo»; datos Odoo en verde. Fuente Odoo: nath.tuctuc.com (KOROSHI, empresa 8), extraído el 27/10/2026. Ordenado por CBM total de mayor a menor.
A3: Implantación = lo que sale a cada tienda (pedidos S-666…) en los 5 días siguientes a su primer envío del modelo, tienda a tienda (hojas «Implantación / Reposición por tienda»); el resto = reposición. % sobre lo comprado. W- = web. Peso neto = bruto − cartones × 1,2 kg.
A4: Aire expedición: densidad < 120 kg/m³ → 20 %; > 200 kg/m³ → 10 %; resto 15 %. Palet = 1,54 m³ (redondeo arriba). TEU = 28 m³. Ubicación = medio palet (0,77 m³); columna = 0,385 m³. ABC: A hasta el 50 % del CBM, B hasta el 84 %, C el resto.
A5: Fila 6 = totales (sumas hasta el último registro; medias ponderadas). Gris = modelo no encontrado en Odoo.
A6: TOTAL | D6: =COUNTA(D8:D474)&" modelos" -> 467 modelos | E6: =SUM(E8:E474) -> 585 | F6: =IFERROR(L6/G6,0) -> 139.91251 | G6: =SUM(G8:G474) -> 2721.3566 | H6: =SUM(H8:H474) -> 1990 | I6: =SUM(I8:I474) -> 3763 | J6: =SUM(J8:J474) -> 7265 | K6: =SUM(K8:K474) -> 97.191307 | L6: =SUM(L8:L474) -> 380751.82 | M6: =SUM(M8:M474) -> 543206 | N6: =SUM(N8:N474) -> 28627 | O6: =IFERROR(G6/M6*1000,0) -> 5.0098059 | P6: =IFERROR(L6/M6*1000,0) -> 700.93449 | Q6: =IFERROR(R6/G6-1,0) -> 0.1659694 | R6: =SUM(R8:R474) -> 3173.0185 | U6: =SUM(U8:U474) -> 524645 | V6: =SUM(V8:V474) -> -13125 | W6: =MIN($W$8:$W$474) -> 46188 | X6: =MAX($X$8:$X$474) -> 46322 | Y6: =SUM(Y8:Y474) -> 53198 | Z6: =SUM(Z8:Z474) -> 312.15698 | AA6: =SUM(AA8:AA474) -> 11.148463 | AB6: =SUM(AB8:AB474) -> 278739 | AC6: =SUM(AC8:AC474) -> 191199 | AD6: =SUM(AD8:AD474) -> 84069 | AE6: =IFERROR(AVERAGE(AE8:AE474),0) -> 37.471092 | AF6: =IFERROR(AVERAGE(AF8:AF474),0) -> 0.74942184 | AG6: =SUM(AG8:AG474) -> 1531 | AH6: =SUM(AH8:AH474) -> 4638 | AI6: =IFERROR(AC6/M6,0) -> 0.35198249 | AJ6: =IFERROR(AD6/M6,0) -> 0.15476449 | AK6: =SUM(AK8:AK474) -> 745.16204 | AL6: =SUM(AL8:AL474) -> 245432 | AM6: =SUM(AM8:AM474) -> 1573.3122 | AN6: =IFERROR(AL6/U6,0) -> 0.46780585 | AO6: =SUM(AO8:AO474) -> 259031 | AP6: =SUM(AP8:AP474) -> 1630.7645 | AQ6: =IFERROR((AC6+AD6)/M6,0) -> 0.50674698 | AR6: =MIN($AR$8:$AR$474) -> 46213 | AS6: =MIN($AS$8:$AS$474) -> 46213 | AT6: =IFERROR(AVERAGE($AT$8:$AT$474),"") -> 10.753555
A7: Género | B7: Familia | C7: Subfamilia | D7: Modelo | E7: Nº packing lists | F7: Densidad (kg/m³) | G7: CBM total (m³) | H7: Palets necesarios | I7: Ubicaciones necesarias | J7: Columnas necesarias | K7: TEUs compra | L7: Peso neto (kg) | M7: Uds compradas (PL) | N7: Cartones | O7: Litros / ud | P7: Gramos / ud (neto) | Q7: % aire expedición | R7: CBM expedición (m³) | S7: % CBM acumulado | T7: ABC volumen | U7: Recibido (uds) | V7: Recibido − comprado | W7: 1ª recepción | X7: Última recepción | Y7: Pendiente recibir (uds) | Z7: Pendiente recibir (m³) | AA7: TEUs pendientes | AB7: Salidas totales (uds) | AC7: Implantación (uds) | AD7: Reposición (uds) | AE7: Tiendas con implantación | AF7: % tiendas implantadas | AG7: Web (uds) | AH7: Otros (uds) | AI7: % implantación (s/ comprado) | AJ7: % reposición (s/ comprado) | AK7: Implantación (m³) | AL7: Stock actual (uds) | AM7: Stock actual (m³) | AN7: % stock (s/ recibido) | AO7: Pendiente servir (comprado − salidas) | AP7: Pendiente servir (m³) | AQ7: Eficacia (impl. + repos. / comprado) | AR7: 1er pedido tienda | AS7: Fecha implantación | AT7: Días recepción → implantación | AU7: Ranking compra | AV7: Ranking salidas | AW7: Dif. ranking (+ vende mejor)
A8: MUJER | B8: CHAQUETA MUJER | C8: PLUMIFERO | D8: 2622JA49 | E8: =COUNTIF('Detalle por artículo'!$K$8:$K$592,D8) -> 5 | F8: =IFERROR(L8/G8,0) -> 89.795094 | G8: =SUMIF('Detalle por artículo'!$K$8:$K$592,$D8,'Detalle por artículo'!$E$8:$E$592) -> 81.696 | H8: =ROUNDUP(G8/1.54,0) -> 54 | I8: =ROUNDUP(G8/0.77,0) -> 107 | J8: =ROUNDUP(G8/0.385,0) -> 213 | K8: =G8/28 -> 2.9177143 | L8: =SUMIF('Detalle por artículo'!$K$8:$K$592,$D8,'Detalle por artículo'!$O$8:$O$592) -> 7335.9 | M8: =SUMIF('Detalle por artículo'!$K$8:$K$592,$D8,'Detalle por artículo'!$I$8:$I$592) -> 6812 | N8: =SUMIF('Detalle por artículo'!$K$8:$K$592,$D8,'Detalle por artículo'!$M$8:$M$592) -> 851 | O8: =IFERROR(G8/M8*1000,0) -> 11.992954 | P8: =IFERROR(L8/M8*1000,0) -> 1076.9084 | Q8: =IF(F8=0,0,IF(F8<120,0.2,IF(F8>200,0.1,0.15))) -> 0.2 | R8: =G8*(1+Q8) -> 98.0352 | S8: =IFERROR(SUM($G$8:G8)/$G$6,0) -> 0.030020321 | T8: =IF(S8<=0.5,"A",IF(S8<=0.84,"B","C")) -> A | U8: 6813 | V8: =U8-M8 -> 1 | W8: 46258 | X8: 46259 | Y8: 28 | Z8: =Y8*O8/1000 -> 0.3358027 | AA8: =Z8/28 -> 0.011992954 | AB8: 1449 | AC8: =IFERROR(INDEX(IMP_TOT,MATCH(D8,IMP_MOD,0)),0) -> 829 | AD8: =IFERROR(INDEX(REP_TOT,MATCH(D8,REP_MOD,0)),0) -> 556 | AE8: =IFERROR(INDEX(IMP_NT,MATCH(D8,IMP_MOD,0)),0) -> 46 | AF8: =IFERROR(AE8/TIENDAS,0) -> 0.92 | AG8: 33 | AH8: 32 | AI8: =IFERROR(AC8/M8,0) -> 0.12169701 | AJ8: =IFERROR(AD8/M8,0) -> 0.081620669 | AK8: =AC8*O8/1000 -> 9.9421585 | AL8: 5356 | AM8: =AL8*O8/1000 -> 64.23426 | AN8: =IFERROR(AL8/U8,0) -> 0.78614414 | AO8: =M8-AB8 -> 5363 | AP8: =AO8*O8/1000 -> 64.31821 | AQ8: =IFERROR((AC8+AD8)/M8,0) -> 0.20331767 | AR8: 46268 | AS8: 46268 | AT8: =IF(OR(W8="",AS8=""),"",AS8-W8) -> 10 | AU8: =IF(M8=0,"",RANK(M8,$M$8:$M$474)) -> 1 | AV8: =IF(AB8=0,"",RANK(AB8,$AB$8:$AB$474)) -> 26 | AW8: =IF(OR(AU8="",AV8=""),"",AU8-AV8) -> -25
A9: MUJER | B9: CHAQUETA MUJER | C9: PLUMIFERO | D9: 2622JA07 | E9: =COUNTIF('Detalle por artículo'!$K$8:$K$592,D9) -> 4 | F9: =IFERROR(L9/G9,0) -> 65.426864 | G9: =SUMIF('Detalle por artículo'!$K$8:$K$592,$D9,'Detalle por artículo'!$E$8:$E$592) -> 76.98 | H9: =ROUNDUP(G9/1.54,0) -> 50 | I9: =ROUNDUP(G9/0.77,0) -> 100 | J9: =ROUNDUP(G9/0.385,0) -> 200 | K9: =G9/28 -> 2.7492857 | L9: =SUMIF('Detalle por artículo'!$K$8:$K$592,$D9,'Detalle por artículo'!$O$8:$O$592) -> 5036.56 | M9: =SUMIF('Detalle por artículo'!$K$8:$K$592,$D9,'Detalle por artículo'!$I$8:$I$592) -> 5606 | N9: =SUMIF('Detalle por artículo'!$K$8:$K$592,$D9,'Detalle por artículo'!$M$8:$M$592) -> 802 | O9: =IFERROR(G9/M9*1000,0) -> 13.731716 | P9: =IFERROR(L9/M9*1000,0) -> 898.42312 | Q9: =IF(F9=0,0,IF(F9<120,0.2,IF(F9>200,0.1,0.15))) -> 0.2 | R9: =G9*(1+Q9) -> 92.376 | S9: =IFERROR(SUM($G$8:G9)/$G$6,0) -> 0.058307684 | T9: =IF(S9<=0.5,"A",IF(S9<=0.84,"B","C")) -> A | U9: 5606 | V9: =U9-M9 -> 0 | W9: 46239 | X9: 46239 | Y9: 0 | Z9: =Y9*O9/1000 -> 0 | AA9: =Z9/28 -> 0 | AB9: 2006 | AC9: =IFERROR(INDEX(IMP_TOT,MATCH(D9,IMP_MOD,0)),0) -> 1372 | AD9: =IFERROR(INDEX(REP_TOT,MATCH(D9,REP_MOD,0)),0) -> 553 | AE9: =IFERROR(INDEX(IMP_NT,MATCH(D9,IMP_MOD,0)),0) -> 41 | AF9: =IFERROR(AE9/TIENDAS,0) -> 0.82 | AG9: 21 | AH9: 60 | AI9: =IFERROR(AC9/M9,0) -> 0.24473778 | AJ9: =IFERROR(AD9/M9,0) -> 0.09864431 | AK9: =AC9*O9/1000 -> 18.839914 | AL9: 3639 | AM9: =AL9*O9/1000 -> 49.969715 | AN9: =IFERROR(AL9/U9,0) -> 0.64912594 | AO9: =M9-AB9 -> 3600 | AP9: =AO9*O9/1000 -> 49.434178 | AQ9: =IFERROR((AC9+AD9)/M9,0) -> 0.34338209 | AR9: 46254 | AS9: 46255 | AT9: =IF(OR(W9="",AS9=""),"",AS9-W9) -> 16 | AU9: =IF(M9=0,"",RANK(M9,$M$8:$M$474)) -> 7 | AV9: =IF(AB9=0,"",RANK(AB9,$AB$8:$AB$474)) -> 11 | AW9: =IF(OR(AU9="",AV9=""),"",AU9-AV9) -> -4
A10: MUJER | B10: CHAQUETA MUJER | C10: PLUMIFERO | D10: 2622JA77 | E10: =COUNTIF('Detalle por artículo'!$K$8:$K$592,D10) -> 6 | F10: =IFERROR(L10/G10,0) -> 107.04091 | G10: =SUMIF('Detalle por artículo'!$K$8:$K$592,$D10,'Detalle por artículo'!$E$8:$E$592) -> 75.53 | H10: =ROUNDUP(G10/1.54,0) -> 50 | I10: =ROUNDUP(G10/0.77,0) -> 99 | J10: =ROUNDUP(G10/0.385,0) -> 197 | K10: =G10/28 -> 2.6975 | L10: =SUMIF('Detalle por artículo'!$K$8:$K$592,$D10,'Detalle por artículo'!$O$8:$O$592) -> 8084.8 | M10: =SUMIF('Detalle por artículo'!$K$8:$K$592,$D10,'Detalle por artículo'!$I$8:$I$592) -> 5459 | N10: =SUMIF('Detalle por artículo'!$K$8:$K$592,$D10,'Detalle por artículo'!$M$8:$M$592) -> 780 | O10: =IFERROR(G10/M10*1000,0) -> 13.835867 | P10: =IFERROR(L10/M10*1000,0) -> 1481.0038 | Q10: =IF(F10=0,0,IF(F10<120,0.2,IF(F10>200,0.1,0.15))) -> 0.2 | R10: =G10*(1+Q10) -> 90.636 | S10: =IFERROR(SUM($G$8:G10)/$G$6,0) -> 0.086062224 | T10: =IF(S10<=0.5,"A",IF(S10<=0.84,"B","C")) -> A | U10: 5465 | V10: =U10-M10 -> 6 | W10: 46258 | X10: 46283 | Y10: 28 | Z10: =Y10*O10/1000 -> 0.38740429 | AA10: =Z10/28 -> 0.013835867 | AB10: 1246 | AC10: =IFERROR(INDEX(IMP_TOT,MATCH(D10,IMP_MOD,0)),0) -> 870 | AD10: =IFERROR(INDEX(REP_TOT,MATCH(D10,REP_MOD,0)),0) -> 363 | AE10: =IFERROR(INDEX(IMP_NT,MATCH(D10,IMP_MOD,0)),0) -> 48 | AF10: =IFERROR(AE10/TIENDAS,0) -> 0.96 | AG10: 13 | AH10: 0 | AI10: =IFERROR(AC10/M10,0) -> 0.15936985 | AJ10: =IFERROR(AD10/M10,0) -> 0.066495695 | AK10: =AC10*O10/1000 -> 12.037205 | AL10: 4218 | AM10: =AL10*O10/1000 -> 58.359689 | AN10: =IFERROR(AL10/U10,0) -> 0.77182068 | AO10: =M10-AB10 -> 4213 | AP10: =AO10*O10/1000 -> 58.290509 | AQ10: =IFERROR((AC10+AD10)/M10,0) -> 0.22586554 | AR10: 46268 | AS10: 46268 | AT10: =IF(OR(W10="",AS10=""),"",AS10-W10) -> 10 | AU10: =IF(M10=0,"",RANK(M10,$M$8:$M$474)) -> 9 | AV10: =IF(AB10=0,"",RANK(AB10,$AB$8:$AB$474)) -> 44 | AW10: =IF(OR(AU10="",AV10=""),"",AU10-AV10) -> -35
A11: MUJER | B11: CHAQUETA MUJER | C11: PLUMIFERO | D11: 2622JA50 | E11: =COUNTIF('Detalle por artículo'!$K$8:$K$592,D11) -> 4 | F11: =IFERROR(L11/G11,0) -> 78.55036 | G11: =SUMIF('Detalle por artículo'!$K$8:$K$592,$D11,'Detalle por artículo'!$E$8:$E$592) -> 72.28 | H11: =ROUNDUP(G11/1.54,0) -> 47 | I11: =ROUNDUP(G11/0.77,0) -> 94 | J11: =ROUNDUP(G11/0.385,0) -> 188 | K11: =G11/28 -> 2.5814286 | L11: =SUMIF('Detalle por artículo'!$K$8:$K$592,$D11,'Detalle por artículo'!$O$8:$O$592) -> 5677.62 | M11: =SUMIF('Detalle por artículo'!$K$8:$K$592,$D11,'Detalle por artículo'!$I$8:$I$592) -> 5261 | N11: =SUMIF('Detalle por artículo'!$K$8:$K$592,$D11,'Detalle por artículo'!$M$8:$M$592) -> 753 | O11: =IFERROR(G11/M11*1000,0) -> 13.738833 | P11: =IFERROR(L11/M11*1000,0) -> 1079.1903 | Q11: =IF(F11=0,0,IF(F11<120,0.2,IF(F11>200,0.1,0.15))) -> 0.2 | R11: =G11*(1+Q11) -> 86.736 | S11: =IFERROR(SUM($G$8:G11)/$G$6,0) -> 0.11262251 | T11: =IF(S11<=0.5,"A",IF(S11<=0.84,"B","C")) -> A | U11: 5263 | V11: =U11-M11 -> 2 | W11: 46239 | X11: 46239 | Y11: 21 | Z11: =Y11*O11/1000 -> 0.28851549 | AA11: =Z11/28 -> 0.010304125 | AB11: 2207 | AC11: =IFERROR(INDEX(IMP_TOT,MATCH(D11,IMP_MOD,0)),0) -> 1473 | AD11: =IFERROR(INDEX(REP_TOT,MATCH(D11,REP_MOD,0)),0) -> 672 | AE11: =IFERROR(INDEX(IMP_NT,MATCH(D11,IMP_MOD,0)),0) -> 45 | AF11: =IFERROR(AE11/TIENDAS,0) -> 0.9 | AG11: 11 | AH11: 60 | AI11: =IFERROR(AC11/M11,0) -> 0.27998479 | AJ11: =IFERROR(AD11/M11,0) -> 0.12773237 | AK11: =AC11*O11/1000 -> 20.237301 | AL11: 3060 | AM11: =AL11*O11/1000 -> 42.040829 | AN11: =IFERROR(AL11/U11,0) -> 0.58141744 | AO11: =M11-AB11 -> 3054 | AP11: =AO11*O11/1000 -> 41.958396 | AQ11: =IFERROR((AC11+AD11)/M11,0) -> 0.40771716 | AR11: 46254 | AS11: 46255 | AT11: =IF(OR(W11="",AS11=""),"",AS11-W11) -> 16 | AU11: =IF(M11=0,"",RANK(M11,$M$8:$M$474)) -> 10 | AV11: =IF(AB11=0,"",RANK(AB11,$AB$8:$AB$474)) -> 6 | AW11: =IF(OR(AU11="",AV11=""),"",AU11-AV11) -> 4
A12: MUJER | B12: CHAQUETA MUJER | C12: PLUMIFERO | D12: 2622JA51 | E12: =COUNTIF('Detalle por artículo'!$K$8:$K$592,D12) -> 4 | F12: =IFERROR(L12/G12,0) -> 80.911111 | G12: =SUMIF('Detalle por artículo'!$K$8:$K$592,$D12,'Detalle por artículo'!$E$8:$E$592) -> 72 | H12: =ROUNDUP(G12/1.54,0) -> 47 | I12: =ROUNDUP(G12/0.77,0) -> 94 | J12: =ROUNDUP(G12/0.385,0) -> 188 | K12: =G12/28 -> 2.5714286 | L12: =SUMIF('Detalle por artículo'!$K$8:$K$592,$D12,'Detalle por artículo'!$O$8:$O$592) -> 5825.6 | M12: =SUMIF('Detalle por artículo'!$K$8:$K$592,$D12,'Detalle por artículo'!$I$8:$I$592) -> 5994 | N12: =SUMIF('Detalle por artículo'!$K$8:$K$592,$D12,'Detalle por artículo'!$M$8:$M$592) -> 750 | O12: =IFERROR(G12/M12*1000,0) -> 12.012012 | P12: =IFERROR(L12/M12*1000,0) -> 971.90524 | Q12: =IF(F12=0,0,IF(F12<120,0.2,IF(F12>200,0.1,0.15))) -> 0.2 | R12: =G12*(1+Q12) -> 86.4 | S12: =IFERROR(SUM($G$8:G12)/$G$6,0) -> 0.1390799 | T12: =IF(S12<=0.5,"A",IF(S12<=0.84,"B","C")) -> A | U12: 5999 | V12: =U12-M12 -> 5 | W12: 46258 | X12: 46259 | Y12: 39 | Z12: =Y12*O12/1000 -> 0.46846847 | AA12: =Z12/28 -> 0.016731017 | AB12: 671 | AC12: =IFERROR(INDEX(IMP_TOT,MATCH(D12,IMP_MOD,0)),0) -> 482 | AD12: =IFERROR(INDEX(REP_TOT,MATCH(D12,REP_MOD,0)),0) -> 158 | AE12: =IFERROR(INDEX(IMP_NT,MATCH(D12,IMP_MOD,0)),0) -> 45 | AF12: =IFERROR(AE12/TIENDAS,0) -> 0.9 | AG12: 23 | AH12: 8 | AI12: =IFERROR(AC12/M12,0) -> 0.080413747 | AJ12: =IFERROR(AD12/M12,0) -> 0.026359693 | AK12: =AC12*O12/1000 -> 5.7897898 | AL12: 5332 | AM12: =AL12*O12/1000 -> 64.048048 | AN12: =IFERROR(AL12/U12,0) -> 0.8888148 | AO12: =M12-AB12 -> 5323 | AP12: =AO12*O12/1000 -> 63.93994 | AQ12: =IFERROR((AC12+AD12)/M12,0) -> 0.10677344 | AR12: 46268 | AS12: 46268 | AT12: =IF(OR(W12="",AS12=""),"",AS12-W12) -> 10 | AU12: =IF(M12=0,"",RANK(M12,$M$8:$M$474)) -> 4 | AV12: =IF(AB12=0,"",RANK(AB12,$AB$8:$AB$474)) -> 142 | AW12: =IF(OR(AU12="",AV12=""),"",AU12-AV12) -> -138
A13: HOMBRE | B13: CHAQUETA HOMBRE | C13: PLUMIFERO | D13: 2621JA59 | E13: =COUNTIF('Detalle por artículo'!$K$8:$K$592,D13) -> 5 | F13: =IFERROR(L13/G13,0) -> 98.429663 | G13: =SUMIF('Detalle por artículo'!$K$8:$K$592,$D13,'Detalle por artículo'!$E$8:$E$592) -> 70.176 | H13: =ROUNDUP(G13/1.54,0) -> 46 | I13: =ROUNDUP(G13/0.77,0) -> 92 | J13: =ROUNDUP(G13/0.385,0) -> 183 | K13: =G13/28 -> 2.5062857 | L13: =SUMIF('Detalle por artículo'!$K$8:$K$592,$D13,'Detalle por artículo'!$O$8:$O$592) -> 6907.4 | M13: =SUMIF('Detalle por artículo'!$K$8:$K$592,$D13,'Detalle por artículo'!$I$8:$I$592) -> 5840 | N13: =SUMIF('Detalle por artículo'!$K$8:$K$592,$D13,'Detalle por artículo'!$M$8:$M$592) -> 731 | O13: =IFERROR(G13/M13*1000,0) -> 12.016438 | P13: =IFERROR(L13/M13*1000,0) -> 1182.774 | Q13: =IF(F13=0,0,IF(F13<120,0.2,IF(F13>200,0.1,0.15))) -> 0.2 | R13: =G13*(1+Q13) -> 84.2112 | S13: =IFERROR(SUM($G$8:G13)/$G$6,0) -> 0.16486704 | T13: =IF(S13<=0.5,"A",IF(S13<=0.84,"B","C")) -> A | U13: 5831 | V13: =U13-M13 -> -9 | W13: 46252 | X13: 46253 | Y13: 12 | Z13: =Y13*O13/1000 -> 0.14419726 | AA13: =Z13/28 -> 0.0051499022 | AB13: 1822 | AC13: =IFERROR(INDEX(IMP_TOT,MATCH(D13,IMP_MOD,0)),0) -> 1188 | AD13: =IFERROR(INDEX(REP_TOT,MATCH(D13,REP_MOD,0)),0) -> 602 | AE13: =IFERROR(INDEX(IMP_NT,MATCH(D13,IMP_MOD,0)),0) -> 46 | AF13: =IFERROR(AE13/TIENDAS,0) -> 0.92 | AG13: 4 | AH13: 32 | AI13: =IFERROR(AC13/M13,0) -> 0.20342466 | AJ13: =IFERROR(AD13/M13,0) -> 0.10308219 | AK13: =AC13*O13/1000 -> 14.275529 | AL13: 4007 | AM13: =AL13*O13/1000 -> 48.149868 | AN13: =IFERROR(AL13/U13,0) -> 0.68718916 | AO13: =M13-AB13 -> 4018 | AP13: =AO13*O13/1000 -> 48.282049 | AQ13: =IFERROR((AC13+AD13)/M13,0) -> 0.30650685 | AR13: 46260 | AS13: 46260 | AT13: =IF(OR(W13="",AS13=""),"",AS13-W13) -> 8 | AU13: =IF(M13=0,"",RANK(M13,$M$8:$M$474)) -> 5 | AV13: =IF(AB13=0,"",RANK(AB13,$AB$8:$AB$474)) -> 14 | AW13: =IF(OR(AU13="",AV13=""),"",AU13-AV13) -> -9
A14: HOMBRE | B14: CHAQUETA HOMBRE | C14: CAZADORA | D14: 2621JA16 | E14: =COUNTIF('Detalle por artículo'!$K$8:$K$592,D14) -> 1 | F14: =IFERROR(L14/G14,0) -> 161.69472 | G14: =SUMIF('Detalle por artículo'!$K$8:$K$592,$D14,'Detalle por artículo'!$E$8:$E$592) -> 68.33 | H14: =ROUNDUP(G14/1.54,0) -> 45 | I14: =ROUNDUP(G14/0.77,0) -> 89 | J14: =ROUNDUP(G14/0.385,0) -> 178 | K14: =G14/28 -> 2.4403571 | L14: =SUMIF('Detalle por artículo'!$K$8:$K$592,$D14,'Detalle por artículo'!$O$8:$O$592) -> 11048.6 | M14: =SUMIF('Detalle por artículo'!$K$8:$K$592,$D14,'Detalle por artículo'!$I$8:$I$592) -> 6643 | N14: =SUMIF('Detalle por artículo'!$K$8:$K$592,$D14,'Detalle por artículo'!$M$8:$M$592) -> 666 | O14: =IFERROR(G14/M14*1000,0) -> 10.286015 | P14: =IFERROR(L14/M14*1000,0) -> 1663.1943 | Q14: =IF(F14=0,0,IF(F14<120,0.2,IF(F14>200,0.1,0.15))) -> 0.15 | R14: =G14*(1+Q14) -> 78.5795 | S14: =IFERROR(SUM($G$8:G14)/$G$6,0) -> 0.18997584 | T14: =IF(S14<=0.5,"A",IF(S14<=0.84,"B","C")) -> A | U14: 6643 | V14: =U14-M14 -> 0 | W14: 46302 | X14: 46304 | Y14: 0 | Z14: =Y14*O14/1000 -> 0 | AA14: =Z14/28 -> 0 | AB14: 555 | AC14: =IFERROR(INDEX(IMP_TOT,MATCH(D14,IMP_MOD,0)),0) -> 439 | AD14: =IFERROR(INDEX(REP_TOT,MATCH(D14,REP_MOD,0)),0) -> 590 | AE14: =IFERROR(INDEX(IMP_NT,MATCH(D14,IMP_MOD,0)),0) -> 49 | AF14: =IFERROR(AE14/TIENDAS,0) -> 0.98 | AG14: 0 | AH14: 0 | AI14: =IFERROR(AC14/M14,0) -> 0.0660846 | AJ14: =IFERROR(AD14/M14,0) -> 0.088815294 | AK14: =AC14*O14/1000 -> 4.5155607 | AL14: 6088 | AM14: =AL14*O14/1000 -> 62.621261 | AN14: =IFERROR(AL14/U14,0) -> 0.91645341 | AO14: =M14-AB14 -> 6088 | AP14: =AO14*O14/1000 -> 62.621261 | AQ14: =IFERROR((AC14+AD14)/M14,0) -> 0.15489989 | AR14: 46303 | AS14: 46304 | AT14: =IF(OR(W14="",AS14=""),"",AS14-W14) -> 2 | AU14: =IF(M14=0,"",RANK(M14,$M$8:$M$474)) -> 2 | AV14: =IF(AB14=0,"",RANK(AB14,$AB$8:$AB$474)) -> 234 | AW14: =IF(OR(AU14="",AV14=""),"",AU14-AV14) -> -232
A15: HOMBRE | B15: CHAQUETA HOMBRE | C15: PLUMIFERO | D15: 2621JA61 | E15: =COUNTIF('Detalle por artículo'!$K$8:$K$592,D15) -> 1 | F15: =IFERROR(L15/G15,0) -> 133.91284 | G15: =SUMIF('Detalle por artículo'!$K$8:$K$592,$D15,'Detalle por artículo'!$E$8:$E$592) -> 64.25 | H15: =ROUNDUP(G15/1.54,0) -> 42 | I15: =ROUNDUP(G15/0.77,0) -> 84 | J15: =ROUNDUP(G15/0.385,0) -> 167 | K15: =G15/28 -> 2.2946429 | L15: =SUMIF('Detalle por artículo'!$K$8:$K$592,$D15,'Detalle por artículo'!$O$8:$O$592) -> 8603.9 | M15: =SUMIF('Detalle por artículo'!$K$8:$K$592,$D15,'Detalle por artículo'!$I$8:$I$592) -> 5820 | N15: =SUMIF('Detalle por artículo'!$K$8:$K$592,$D15,'Detalle por artículo'!$M$8:$M$592) -> 583 | O15: =IFERROR(G15/M15*1000,0) -> 11.039519 | P15: =IFERROR(L15/M15*1000,0) -> 1478.3333 | Q15: =IF(F15=0,0,IF(F15<120,0.2,IF(F15>200,0.1,0.15))) -> 0.15 | R15: =G15*(1+Q15) -> 73.8875 | S15: =IFERROR(SUM($G$8:G15)/$G$6,0) -> 0.21358539 | T15: =IF(S15<=0.5,"A",IF(S15<=0.84,"B","C")) -> A | U15: 5830 | V15: =U15-M15 -> 10 | W15: 46315 | X15: 46315 | Y15: 0 | Z15: =Y15*O15/1000 -> 0 | AA15: =Z15/28 -> 0 | AB15: 0 | AC15: =IFERROR(INDEX(IMP_TOT,MATCH(D15,IMP_MOD,0)),0) -> 0 | AD15: =IFERROR(INDEX(REP_TOT,MATCH(D15,REP_MOD,0)),0) -> 0 | AE15: =IFERROR(INDEX(IMP_NT,MATCH(D15,IMP_MOD,0)),0) -> 0 | AF15: =IFERROR(AE15/TIENDAS,0) -> 0 | AG15: 0 | AH15: 0 | AI15: =IFERROR(AC15/M15,0) -> 0 | AJ15: =IFERROR(AD15/M15,0) -> 0 | AK15: =AC15*O15/1000 -> 0 | AL15: 5830 | AM15: =AL15*O15/1000 -> 64.360395 | AN15: =IFERROR(AL15/U15,0) -> 1 | AO15: =M15-AB15 -> 5820 | AP15: =AO15*O15/1000 -> 64.25 | AQ15: =IFERROR((AC15+AD15)/M15,0) -> 0 | AT15: =IF(OR(W15="",AS15=""),"",AS15-W15) | AU15: =IF(M15=0,"",RANK(M15,$M$8:$M$474)) -> 6 | AV15: =IF(AB15=0,"",RANK(AB15,$AB$8:$AB$474)) | AW15: =IF(OR(AU15="",AV15=""),"",AU15-AV15)
A16: HOMBRE | B16: CHAQUETA HOMBRE | C16: PLUMIFERO | D16: 2621JA49 | E16: =COUNTIF('Detalle por artículo'!$K$8:$K$592,D16) -> 1 | F16: =IFERROR(L16/G16,0) -> 110.08812 | G16: =SUMIF('Detalle por artículo'!$K$8:$K$592,$D16,'Detalle por artículo'!$E$8:$E$592) -> 47.66 | H16: =ROUNDUP(G16/1.54,0) -> 31 | I16: =ROUNDUP(G16/0.77,0) -> 62 | J16: =ROUNDUP(G16/0.385,0) -> 124 | K16: =G16/28 -> 1.7021429 | L16: =SUMIF('Detalle por artículo'!$K$8:$K$592,$D16,'Detalle por artículo'!$O$8:$O$592) -> 5246.8 | M16: =SUMIF('Detalle por artículo'!$K$8:$K$592,$D16,'Detalle por artículo'!$I$8:$I$592) -> 6556 | N16: =SUMIF('Detalle por artículo'!$K$8:$K$592,$D16,'Detalle por artículo'!$M$8:$M$592) -> 439 | O16: =IFERROR(G16/M16*1000,0) -> 7.2696766 | P16: =IFERROR(L16/M16*1000,0) -> 800.30506 | Q16: =IF(F16=0,0,IF(F16<120,0.2,IF(F16>200,0.1,0.15))) -> 0.2 | R16: =G16*(1+Q16) -> 57.192 | S16: =IFERROR(SUM($G$8:G16)/$G$6,0) -> 0.23109871 | T16: =IF(S16<=0.5,"A",IF(S16<=0.84,"B","C")) -> A | U16: 6549 | V16: =U16-M16 -> -7 | W16: 46302 | X16: 46302 | Y16: 7 | Z16: =Y16*O16/1000 -> 0.050887736 | AA16: =Z16/28 -> 0.0018174192 | AB16: 1874 | AC16: =IFERROR(INDEX(IMP_TOT,MATCH(D16,IMP_MOD,0)),0) -> 1375 | AD16: =IFERROR(INDEX(REP_TOT,MATCH(D16,REP_MOD,0)),0) -> 494 | AE16: =IFERROR(INDEX(IMP_NT,MATCH(D16,IMP_MOD,0)),0) -> 48 | AF16: =IFERROR(AE16/TIENDAS,0) -> 0.96 | AG16: 5 | AH16: 0 | AI16: =IFERROR(AC16/M16,0) -> 0.20973154 | AJ16: =IFERROR(AD16/M16,0) -> 0.075350824 | AK16: =AC16*O16/1000 -> 9.9958054 | AL16: 4675 | AM16: =AL16*O16/1000 -> 33.985738 | AN16: =IFERROR(AL16/U16,0) -> 0.71384944 | AO16: =M16-AB16 -> 4682 | AP16: =AO16*O16/1000 -> 34.036626 | AQ16: =IFERROR((AC16+AD16)/M16,0) -> 0.28508237 | AR16: 46303 | AS16: 46304 | AT16: =IF(OR(W16="",AS16=""),"",AS16-W16) -> 2 | AU16: =IF(M16=0,"",RANK(M16,$M$8:$M$474)) -> 3 | AV16: =IF(AB16=0,"",RANK(AB16,$AB$8:$AB$474)) -> 12 | AW16: =IF(OR(AU16="",AV16=""),"",AU16-AV16) -> -9
A17: HOMBRE | B17: CHAQUETA HOMBRE | C17: PLUMIFERO | D17: 2621JA57 | E17: =COUNTIF('Detalle por artículo'!$K$8:$K$592,D17) -> 1 | F17: =IFERROR(L17/G17,0) -> 116.13291 | G17: =SUMIF('Detalle por artículo'!$K$8:$K$592,$D17,'Detalle por artículo'!$E$8:$E$592) -> 47.4 | H17: =ROUNDUP(G17/1.54,0) -> 31 | I17: =ROUNDUP(G17/0.77,0) -> 62 | J17: =ROUNDUP(G17/0.385,0) -> 124 | K17: =G17/28 -> 1.6928571 | L17: =SUMIF('Detalle por artículo'!$K$8:$K$592,$D17,'Detalle por artículo'!$O$8:$O$592) -> 5504.7 | M17: =SUMIF('Detalle por artículo'!$K$8:$K$592,$D17,'Detalle por artículo'!$I$8:$I$592) -> 4083 | N17: =SUMIF('Detalle por artículo'!$K$8:$K$592,$D17,'Detalle por artículo'!$M$8:$M$592) -> 454 | O17: =IFERROR(G17/M17*1000,0) -> 11.609111 | P17: =IFERROR(L17/M17*1000,0) -> 1348.1999 | Q17: =IF(F17=0,0,IF(F17<120,0.2,IF(F17>200,0.1,0.15))) -> 0.2 | R17: =G17*(1+Q17) -> 56.88 | S17: =IFERROR(SUM($G$8:G17)/$G$6,0) -> 0.24851649 | T17: =IF(S17<=0.5,"A",IF(S17<=0.84,"B","C")) -> A | U17: 4079 | V17: =U17-M17 -> -4 | W17: 46308 | X17: 46308 | Y17: 47 | Z17: =Y17*O17/1000 -> 0.54562821 | AA17: =Z17/28 -> 0.019486722 | AB17: 0 | AC17: =IFERROR(INDEX(IMP_TOT,MATCH(D17,IMP_MOD,0)),0) -> 0 | AD17: =IFERROR(INDEX(REP_TOT,MATCH(D17,REP_MOD,0)),0) -> 0 | AE17: =IFERROR(INDEX(IMP_NT,MATCH(D17,IMP_MOD,0)),0) -> 0 | AF17: =IFERROR(AE17/TIENDAS,0) -> 0 | AG17: 0 | AH17: 0 | AI17: =IFERROR(AC17/M17,0) -> 0 | AJ17: =IFERROR(AD17/M17,0) -> 0 | AK17: =AC17*O17/1000 -> 0 | AL17: 4079 | AM17: =AL17*O17/1000 -> 47.353564 | AN17: =IFERROR(AL17/U17,0) -> 1 | AO17: =M17-AB17 -> 4083 | AP17: =AO17*O17/1000 -> 47.4 | AQ17: =IFERROR((AC17+AD17)/M17,0) -> 0 | AT17: =IF(OR(W17="",AS17=""),"",AS17-W17) | AU17: =IF(M17=0,"",RANK(M17,$M$8:$M$474)) -> 13 | AV17: =IF(AB17=0,"",RANK(AB17,$AB$8:$AB$474)) | AW17: =IF(OR(AU17="",AV17=""),"",AU17-AV17)
A18: HOMBRE | B18: CHAQUETA HOMBRE | C18: PARKA | D18: 2621JA18 | E18: =COUNTIF('Detalle por artículo'!$K$8:$K$592,D18) -> 1 | F18: =IFERROR(L18/G18,0) -> 164.65517 | G18: =SUMIF('Detalle por artículo'!$K$8:$K$592,$D18,'Detalle por artículo'!$E$8:$E$592) -> 43.5 | H18: =ROUNDUP(G18/1.54,0) -> 29 | I18: =ROUNDUP(G18/0.77,0) -> 57 | J18: =ROUNDUP(G18/0.385,0) -> 113 | K18: =G18/28 -> 1.5535714 | L18: =SUMIF('Detalle por artículo'!$K$8:$K$592,$D18,'Detalle por artículo'!$O$8:$O$592) -> 7162.5 | M18: =SUMIF('Detalle por artículo'!$K$8:$K$592,$D18,'Detalle por artículo'!$I$8:$I$592) -> 3746 | N18: =SUMIF('Detalle por artículo'!$K$8:$K$592,$D18,'Detalle por artículo'!$M$8:$M$592) -> 375 | O18: =IFERROR(G18/M18*1000,0) -> 11.612387 | P18: =IFERROR(L18/M18*1000,0) -> 1912.0395 | Q18: =IF(F18=0,0,IF(F18<120,0.2,IF(F18>200,0.1,0.15))) -> 0.15 | R18: =G18*(1+Q18) -> 50.025 | S18: =IFERROR(SUM($G$8:G18)/$G$6,0) -> 0.26450117 | T18: =IF(S18<=0.5,"A",IF(S18<=0.84,"B","C")) -> A | U18: 3746 | V18: =U18-M18 -> 0 | W18: 46308 | X18: 46308 | Y18: 0 | Z18: =Y18*O18/1000 -> 0 | AA18: =Z18/28 -> 0 | AB18: 0 | AC18: =IFERROR(INDEX(IMP_TOT,MATCH(D18,IMP_MOD,0)),0) -> 0 | AD18: =IFERROR(INDEX(REP_TOT,MATCH(D18,REP_MOD,0)),0) -> 0 | AE18: =IFERROR(INDEX(IMP_NT,MATCH(D18,IMP_MOD,0)),0) -> 0 | AF18: =IFERROR(AE18/TIENDAS,0) -> 0 | AG18: 0 | AH18: 0 | AI18: =IFERROR(AC18/M18,0) -> 0 | AJ18: =IFERROR(AD18/M18,0) -> 0 | AK18: =AC18*O18/1000 -> 0 | AL18: 3746 | AM18: =AL18*O18/1000 -> 43.5 | AN18: =IFERROR(AL18/U18,0) -> 1 | AO18: =M18-AB18 -> 3746 | AP18: =AO18*O18/1000 -> 43.5 | AQ18: =IFERROR((AC18+AD18)/M18,0) -> 0 | AT18: =IF(OR(W18="",AS18=""),"",AS18-W18) | AU18: =IF(M18=0,"",RANK(M18,$M$8:$M$474)) -> 17 | AV18: =IF(AB18=0,"",RANK(AB18,$AB$8:$AB$474)) | AW18: =IF(OR(AU18="",AV18=""),"",AU18-AV18)
A19: HOMBRE | B19: CHAQUETA HOMBRE | C19: PLUMIFERO | D19: 2621JA54 | E19: =COUNTIF('Detalle por artículo'!$K$8:$K$592,D19) -> 3 | F19: =IFERROR(L19/G19,0) -> 101.97526 | G19: =SUMIF('Detalle por artículo'!$K$8:$K$592,$D19,'Detalle por artículo'!$E$8:$E$592) -> 43.488 | H19: =ROUNDUP(G19/1.54,0) -> 29 | I19: =ROUNDUP(G19/0.77,0) -> 57 | J19: =ROUNDUP(G19/0.385,0) -> 113 | K19: =G19/28 -> 1.5531429 | L19: =SUMIF('Detalle por artículo'!$K$8:$K$592,$D19,'Detalle por artículo'!$O$8:$O$592) -> 4434.7 | M19: =SUMIF('Detalle por artículo'!$K$8:$K$592,$D19,'Detalle por artículo'!$I$8:$I$592) -> 3609 | N19: =SUMIF('Detalle por artículo'!$K$8:$K$592,$D19,'Detalle por artículo'!$M$8:$M$592) -> 453 | O19: =IFERROR(G19/M19*1000,0) -> 12.049875 | P19: =IFERROR(L19/M19*1000,0) -> 1228.7891 | Q19: =IF(F19=0,0,IF(F19<120,0.2,IF(F19>200,0.1,0.15))) -> 0.2 | R19: =G19*(1+Q19) -> 52.1856 | S19: =IFERROR(SUM($G$8:G19)/$G$6,0) -> 0.28048143 | T19: =IF(S19<=0.5,"A",IF(S19<=0.84,"B","C")) -> A | U19: 3610 | V19: =U19-M19 -> 1 | W19: 46253 | X19: 46253 | Y19: 0 | Z19: =Y19*O19/1000 -> 0 | AA19: =Z19/28 -> 0 | AB19: 1374 | AC19: =IFERROR(INDEX(IMP_TOT,MATCH(D19,IMP_MOD,0)),0) -> 1120 | AD19: =IFERROR(INDEX(REP_TOT,MATCH(D19,REP_MOD,0)),0) -> 243 | AE19: =IFERROR(INDEX(IMP_NT,MATCH(D19,IMP_MOD,0)),0) -> 48 | AF19: =IFERROR(AE19/TIENDAS,0) -> 0.96 | AG19: 11 | AH19: 0 | AI19: =IFERROR(AC19/M19,0) -> 0.31033527 | AJ19: =IFERROR(AD19/M19,0) -> 0.067331671 | AK19: =AC19*O19/1000 -> 13.49586 | AL19: 2234 | AM19: =AL19*O19/1000 -> 26.919421 | AN19: =IFERROR(AL19/U19,0) -> 0.61883657 | AO19: =M19-AB19 -> 2235 | AP19: =AO19*O19/1000 -> 26.931471 | AQ19: =IFERROR((AC19+AD19)/M19,0) -> 0.37766694 | AR19: 46260 | AS19: 46260 | AT19: =IF(OR(W19="",AS19=""),"",AS19-W19) -> 7 | AU19: =IF(M19=0,"",RANK(M19,$M$8:$M$474)) -> 19 | AV19: =IF(AB19=0,"",RANK(AB19,$AB$8:$AB$474)) -> 31 | AW19: =IF(OR(AU19="",AV19=""),"",AU19-AV19) -> -12
A20: HOMBRE | B20: CHAQUETA HOMBRE | C20: PLUMIFERO | D20: 2621JA56 | E20: =COUNTIF('Detalle por artículo'!$K$8:$K$592,D20) -> 1 | F20: =IFERROR(L20/G20,0) -> 164.75166 | G20: =SUMIF('Detalle por artículo'!$K$8:$K$592,$D20,'Detalle por artículo'!$E$8:$E$592) -> 42.28 | H20: =ROUNDUP(G20/1.54,0) -> 28 | I20: =ROUNDUP(G20/0.77,0) -> 55 | J20: =ROUNDUP(G20/0.385,0) -> 110 | K20: =G20/28 -> 1.51 | L20: =SUMIF('Detalle por artículo'!$K$8:$K$592,$D20,'Detalle por artículo'!$O$8:$O$592) -> 6965.7 | M20: =SUMIF('Detalle por artículo'!$K$8:$K$592,$D20,'Detalle por artículo'!$I$8:$I$592) -> 4031 | N20: =SUMIF('Detalle por artículo'!$K$8:$K$592,$D20,'Detalle por artículo'!$M$8:$M$592) -> 405 | O20: =IFERROR(G20/M20*1000,0) -> 10.488712 | P20: =IFERROR(L20/M20*1000,0) -> 1728.0327 | Q20: =IF(F20=0,0,IF(F20<120,0.2,IF(F20>200,0.1,0.15))) -> 0.15 | R20: =G20*(1+Q20) -> 48.622 | S20: =IFERROR(SUM($G$8:G20)/$G$6,0) -> 0.2960178 | T20: =IF(S20<=0.5,"A",IF(S20<=0.84,"B","C")) -> A | U20: 4031 | V20: =U20-M20 -> 0 | W20: 46309 | X20: 46309 | Y20: 0 | Z20: =Y20*O20/1000 -> 0 | AA20: =Z20/28 -> 0 | AB20: 0 | AC20: =IFERROR(INDEX(IMP_TOT,MATCH(D20,IMP_MOD,0)),0) -> 0 | AD20: =IFERROR(INDEX(REP_TOT,MATCH(D20,REP_MOD,0)),0) -> 0 | AE20: =IFERROR(INDEX(IMP_NT,MATCH(D20,IMP_MOD,0)),0) -> 0 | AF20: =IFERROR(AE20/TIENDAS,0) -> 0 | AG20: 0 | AH20: 0 | AI20: =IFERROR(AC20/M20,0) -> 0 | AJ20: =IFERROR(AD20/M20,0) -> 0 | AK20: =AC20*O20/1000 -> 0 | AL20: 4031 | AM20: =AL20*O20/1000 -> 42.28 | AN20: =IFERROR(AL20/U20,0) -> 1 | AO20: =M20-AB20 -> 4031 | AP20: =AO20*O20/1000 -> 42.28 | AQ20: =IFERROR((AC20+AD20)/M20,0) -> 0 | AT20: =IF(OR(W20="",AS20=""),"",AS20-W20) | AU20: =IF(M20=0,"",RANK(M20,$M$8:$M$474)) -> 15 | AV20: =IF(AB20=0,"",RANK(AB20,$AB$8:$AB$474)) | AW20: =IF(OR(AU20="",AV20=""),"",AU20-AV20)
A21: HOMBRE | B21: CHAQUETA HOMBRE | C21: CAZADORA | D21: 2621JA00 | E21: =COUNTIF('Detalle por artículo'!$K$8:$K$592,D21) -> 1 | F21: =IFERROR(L21/G21,0) -> 164.30836 | G21: =SUMIF('Detalle por artículo'!$K$8:$K$592,$D21,'Detalle por artículo'!$E$8:$E$592) -> 30.912 | H21: =ROUNDUP(G21/1.54,0) -> 21 | I21: =ROUNDUP(G21/0.77,0) -> 41 | J21: =ROUNDUP(G21/0.385,0) -> 81 | K21: =G21/28 -> 1.104 | L21: =SUMIF('Detalle por artículo'!$K$8:$K$592,$D21,'Detalle por artículo'!$O$8:$O$592) -> 5079.1 | M21: =SUMIF('Detalle por artículo'!$K$8:$K$592,$D21,'Detalle por artículo'!$I$8:$I$592) -> 4804 | N21: =SUMIF('Detalle por artículo'!$K$8:$K$592,$D21,'Detalle por artículo'!$M$8:$M$592) -> 322 | O21: =IFERROR(G21/M21*1000,0) -> 6.4346378 | P21: =IFERROR(L21/M21*1000,0) -> 1057.2648 | Q21: =IF(F21=0,0,IF(F21<120,0.2,IF(F21>200,0.1,0.15))) -> 0.15 | R21: =G21*(1+Q21) -> 35.5488 | S21: =IFERROR(SUM($G$8:G21)/$G$6,0) -> 0.30737684 | T21: =IF(S21<=0.5,"A",IF(S21<=0.84,"B","C")) -> A | U21: 4775 | V21: =U21-M21 -> -29 | W21: 46281 | X21: 46281 | Y21: 38 | Z21: =Y21*O21/1000 -> 0.24451624 | AA21: =Z21/28 -> 0.0087327227 | AB21: 2320 | AC21: =IFERROR(INDEX(IMP_TOT,MATCH(D21,IMP_MOD,0)),0) -> 1317 | AD21: =IFERROR(INDEX(REP_TOT,MATCH(D21,REP_MOD,0)),0) -> 961 | AE21: =IFERROR(INDEX(IMP_NT,MATCH(D21,IMP_MOD,0)),0) -> 48 | AF21: =IFERROR(AE21/TIENDAS,0) -> 0.96 | AG21: 18 | AH21: 27 | AI21: =IFERROR(AC21/M21,0) -> 0.27414654 | AJ21: =IFERROR(AD21/M21,0) -> 0.20004163 | AK21: =AC21*O21/1000 -> 8.474418 | AL21: 2446 | AM21: =AL21*O21/1000 -> 15.739124 | AN21: =IFERROR(AL21/U21,0) -> 0.51225131 | AO21: =M21-AB21 -> 2484 | AP21: =AO21*O21/1000 -> 15.98364 | AQ21: =IFERROR((AC21+AD21)/M21,0) -> 0.47418818 | AR21: 46281 | AS21: 46282 | AT21: =IF(OR(W21="",AS21=""),"",AS21-W21) -> 1 | AU21: =IF(M21=0,"",RANK(M21,$M$8:$M$474)) -> 11 | AV21: =IF(AB21=0,"",RANK(AB21,$AB$8:$AB$474)) -> 4 | AW21: =IF(OR(AU21="",AV21=""),"",AU21-AV21) -> 7
A22: HOMBRE | B22: CHAQUETA HOMBRE | C22: CAZADORA | D22: 2621JA22 | E22: =COUNTIF('Detalle por artículo'!$K$8:$K$592,D22) -> 1 | F22: =IFERROR(L22/G22,0) -> 175.4758 | G22: =SUMIF('Detalle por artículo'!$K$8:$K$592,$D22,'Detalle por artículo'!$E$8:$E$592) -> 29.424 | H22: =ROUNDUP(G22/1.54,0) -> 20 | I22: =ROUNDUP(G22/0.77,0) -> 39 | J22: =ROUNDUP(G22/0.385,0) -> 77 | K22: =G22/28 -> 1.0508571 | L22: =SUMIF('Detalle por artículo'!$K$8:$K$592,$D22,'Detalle por artículo'!$O$8:$O$592) -> 5163.2 | M22: =SUMIF('Detalle por artículo'!$K$8:$K$592,$D22,'Detalle por artículo'!$I$8:$I$592) -> 4034 | N22: =SUMIF('Detalle por artículo'!$K$8:$K$592,$D22,'Detalle por artículo'!$M$8:$M$592) -> 271 | O22: =IFERROR(G22/M22*1000,0) -> 7.294001 | P22: =IFERROR(L22/M22*1000,0) -> 1279.9207 | Q22: =IF(F22=0,0,IF(F22<120,0.2,IF(F22>200,0.1,0.15))) -> 0.15 | R22: =G22*(1+Q22) -> 33.8376 | S22: =IFERROR(SUM($G$8:G22)/$G$6,0) -> 0.3181891 | T22: =IF(S22<=0.5,"A",IF(S22<=0.84,"B","C")) -> A | U22: 4035 | V22: =U22-M22 -> 1 | W22: 46272 | X22: 46272 | Y22: 4065 | Z22: =Y22*O22/1000 -> 29.650114 | AA22: =Z22/28 -> 1.0589326 | AB22: 2292 | AC22: =IFERROR(INDEX(IMP_TOT,MATCH(D22,IMP_MOD,0)),0) -> 1505 | AD22: =IFERROR(INDEX(REP_TOT,MATCH(D22,REP_MOD,0)),0) -> 750 | AE22: =IFERROR(INDEX(IMP_NT,MATCH(D22,IMP_MOD,0)),0) -> 49 | AF22: =IFERROR(AE22/TIENDAS,0) -> 0.98 | AG22: 17 | AH22: 24 | AI22: =IFERROR(AC22/M22,0) -> 0.37307883 | AJ22: =IFERROR(AD22/M22,0) -> 0.18591968 | AK22: =AC22*O22/1000 -> 10.977471 | AL22: 1754 | AM22: =AL22*O22/1000 -> 12.793678 | AN22: =IFERROR(AL22/U22,0) -> 0.43469641 | AO22: =M22-AB22 -> 1742 | AP22: =AO22*O22/1000 -> 12.70615 | AQ22: =IFERROR((AC22+AD22)/M22,0) -> 0.55899851 | AR22: 46274 | AS22: 46275 | AT22: =IF(OR(W22="",AS22=""),"",AS22-W22) -> 3 | AU22: =IF(M22=0,"",RANK(M22,$M$8:$M$474)) -> 14 | AV22: =IF(AB22=0,"",RANK(AB22,$AB$8:$AB$474)) -> 5 | AW22: =IF(OR(AU22="",AV22=""),"",AU22-AV22) -> 9
A23: MUJER | B23: CHAQUETA MUJER | C23: PARKA | D23: 2622JA72 | E23: =COUNTIF('Detalle por artículo'!$K$8:$K$592,D23) -> 1 | F23: =IFERROR(L23/G23,0) -> 111.50738 | G23: =SUMIF('Detalle por artículo'!$K$8:$K$592,$D23,'Detalle por artículo'!$E$8:$E$592) -> 25.74 | H23: =ROUNDUP(G23/1.54,0) -> 17 | I23: =ROUNDUP(G23/0.77,0) -> 34 | J23: =ROUNDUP(G23/0.385,0) -> 67 | K23: =G23/28 -> 0.91928571 | L23: =SUMIF('Detalle por artículo'!$K$8:$K$592,$D23,'Detalle por artículo'!$O$8:$O$592) -> 2870.2 | M23: =SUMIF('Detalle por artículo'!$K$8:$K$592,$D23,'Detalle por artículo'!$I$8:$I$592) -> 1915 | N23: =SUMIF('Detalle por artículo'!$K$8:$K$592,$D23,'Detalle por artículo'!$M$8:$M$592) -> 240 | O23: =IFERROR(G23/M23*1000,0) -> 13.441253 | P23: =IFERROR(L23/M23*1000,0) -> 1498.799 | Q23: =IF(F23=0,0,IF(F23<120,0.2,IF(F23>200,0.1,0.15))) -> 0.2 | R23: =G23*(1+Q23) -> 30.888 | S23: =IFERROR(SUM($G$8:G23)/$G$6,0) -> 0.32764762 | T23: =IF(S23<=0.5,"A",IF(S23<=0.84,"B","C")) -> A | U23: 1915 | V23: =U23-M23 -> 0 | W23: 46286 | X23: 46286 | Y23: 32 | Z23: =Y23*O23/1000 -> 0.4301201 | AA23: =Z23/28 -> 0.015361432 | AB23: 591 | AC23: =IFERROR(INDEX(IMP_TOT,MATCH(D23,IMP_MOD,0)),0) -> 584 | AD23: =IFERROR(INDEX(REP_TOT,MATCH(D23,REP_MOD,0)),0) -> 0 | AE23: =IFERROR(INDEX(IMP_NT,MATCH(D23,IMP_MOD,0)),0) -> 30 | AF23: =IFERROR(AE23/TIENDAS,0) -> 0.6 | AG23: 7 | AH23: 0 | AI23: =IFERROR(AC23/M23,0) -> 0.30496084 | AJ23: =IFERROR(AD23/M23,0) -> 0 | AK23: =AC23*O23/1000 -> 7.8496919 | AL23: 1324 | AM23: =AL23*O23/1000 -> 17.796219 | AN23: =IFERROR(AL23/U23,0) -> 0.69138381 | AO23: =M23-AB23 -> 1324 | AP23: =AO23*O23/1000 -> 17.796219 | AQ23: =IFERROR((AC23+AD23)/M23,0) -> 0.30496084 | AR23: 46293 | AS23: 46294 | AT23: =IF(OR(W23="",AS23=""),"",AS23-W23) -> 8 | AU23: =IF(M23=0,"",RANK(M23,$M$8:$M$474)) -> 46 | AV23: =IF(AB23=0,"",RANK(AB23,$AB$8:$AB$474)) -> 203 | AW23: =IF(OR(AU23="",AV23=""),"",AU23-AV23) -> -157
A24: MUJER | B24: CHAQUETA MUJER | C24: PLUMIFERO | D24: 2622JA56 | E24: =COUNTIF('Detalle por artículo'!$K$8:$K$592,D24) -> 2 | F24: =IFERROR(L24/G24,0) -> 123.54219 | G24: =SUMIF('Detalle por artículo'!$K$8:$K$592,$D24,'Detalle por artículo'!$E$8:$E$592) -> 24.866 | H24: =ROUNDUP(G24/1.54,0) -> 17 | I24: =ROUNDUP(G24/0.77,0) -> 33 | J24: =ROUNDUP(G24/0.385,0) -> 65 | K24: =G24/28 -> 0.88807143 | L24: =SUMIF('Detalle por artículo'!$K$8:$K$592,$D24,'Detalle por artículo'!$O$8:$O$592) -> 3072 | M24: =SUMIF('Detalle por artículo'!$K$8:$K$592,$D24,'Detalle por artículo'!$I$8:$I$592) -> 1826 | N24: =SUMIF('Detalle por artículo'!$K$8:$K$592,$D24,'Detalle por artículo'!$M$8:$M$592) -> 260 | O24: =IFERROR(G24/M24*1000,0) -> 13.617744 | P24: =IFERROR(L24/M24*1000,0) -> 1682.3658 | Q24: =IF(F24=0,0,IF(F24<120,0.2,IF(F24>200,0.1,0.15))) -> 0.15 | R24: =G24*(1+Q24) -> 28.5959 | S24: =IFERROR(SUM($G$8:G24)/$G$6,0) -> 0.33678497 | T24: =IF(S24<=0.5,"A",IF(S24<=0.84,"B","C")) -> A | U24: 1827 | V24: =U24-M24 -> 1 | W24: 46282 | X24: 46282 | Y24: 14 | Z24: =Y24*O24/1000 -> 0.19064841 | AA24: =Z24/28 -> 0.0068088719 | AB24: 386 | AC24: =IFERROR(INDEX(IMP_TOT,MATCH(D24,IMP_MOD,0)),0) -> 367 | AD24: =IFERROR(INDEX(REP_TOT,MATCH(D24,REP_MOD,0)),0) -> 5 | AE24: =IFERROR(INDEX(IMP_NT,MATCH(D24,IMP_MOD,0)),0) -> 37 | AF24: =IFERROR(AE24/TIENDAS,0) -> 0.74 | AG24: 6 | AH24: 8 | AI24: =IFERROR(AC24/M24,0) -> 0.20098576 | AJ24: =IFERROR(AD24/M24,0) -> 0.0027382256 | AK24: =AC24*O24/1000 -> 4.9977119 | AL24: 1441 | AM24: =AL24*O24/1000 -> 19.623169 | AN24: =IFERROR(AL24/U24,0) -> 0.78872469 | AO24: =M24-AB24 -> 1440 | AP24: =AO24*O24/1000 -> 19.609551 | AQ24: =IFERROR((AC24+AD24)/M24,0) -> 0.20372399 | AR24: 46285 | AS24: 46287 | AT24: =IF(OR(W24="",AS24=""),"",AS24-W24) -> 5 | AU24: =IF(M24=0,"",RANK(M24,$M$8:$M$474)) -> 53 | AV24: =IF(AB24=0,"",RANK(AB24,$AB$8:$AB$474)) -> 331 | AW24: =IF(OR(AU24="",AV24=""),"",AU24-AV24) -> -278
A25: MUJER | B25: CHAQUETA MUJER | C25: PLUMIFERO | D25: 2622JA76 | E25: =COUNTIF('Detalle por artículo'!$K$8:$K$592,D25) -> 2 | F25: =IFERROR(L25/G25,0) -> 90.894466 | G25: =SUMIF('Detalle por artículo'!$K$8:$K$592,$D25,'Detalle por artículo'!$E$8:$E$592) -> 24.864 | H25: =ROUNDUP(G25/1.54,0) -> 17 | I25: =ROUNDUP(G25/0.77,0) -> 33 | J25: =ROUNDUP(G25/0.385,0) -> 65 | K25: =G25/28 -> 0.888 | L25: =SUMIF('Detalle por artículo'!$K$8:$K$592,$D25,'Detalle por artículo'!$O$8:$O$592) -> 2260 | M25: =SUMIF('Detalle por artículo'!$K$8:$K$592,$D25,'Detalle por artículo'!$I$8:$I$592) -> 2071 | N25: =SUMIF('Detalle por artículo'!$K$8:$K$592,$D25,'Detalle por artículo'!$M$8:$M$592) -> 259 | O25: =IFERROR(G25/M25*1000,0) -> 12.005794 | P25: =IFERROR(L25/M25*1000,0) -> 1091.2603 | Q25: =IF(F25=0,0,IF(F25<120,0.2,IF(F25>200,0.1,0.15))) -> 0.2 | R25: =G25*(1+Q25) -> 29.8368 | S25: =IFERROR(SUM($G$8:G25)/$G$6,0) -> 0.34592159 | T25: =IF(S25<=0.5,"A",IF(S25<=0.84,"B","C")) -> A | U25: 2067 | V25: =U25-M25 -> -4 | W25: 46282 | X25: 46282 | Y25: 13 | Z25: =Y25*O25/1000 -> 0.15607533 | AA25: =Z25/28 -> 0.0055741188 | AB25: 610 | AC25: =IFERROR(INDEX(IMP_TOT,MATCH(D25,IMP_MOD,0)),0) -> 573 | AD25: =IFERROR(INDEX(REP_TOT,MATCH(D25,REP_MOD,0)),0) -> 18 | AE25: =IFERROR(INDEX(IMP_NT,MATCH(D25,IMP_MOD,0)),0) -> 37 | AF25: =IFERROR(AE25/TIENDAS,0) -> 0.74 | AG25: 19 | AH25: 0 | AI25: =IFERROR(AC25/M25,0) -> 0.27667793 | AJ25: =IFERROR(AD25/M25,0) -> 0.0086914534 | AK25: =AC25*O25/1000 -> 6.8793201 | AL25: 1457 | AM25: =AL25*O25/1000 -> 17.492442 | AN25: =IFERROR(AL25/U25,0) -> 0.70488631 | AO25: =M25-AB25 -> 1461 | AP25: =AO25*O25/1000 -> 17.540465 | AQ25: =IFERROR((AC25+AD25)/M25,0) -> 0.28536939 | AR25: 46285 | AS25: 46287 | AT25: =IF(OR(W25="",AS25=""),"",AS25-W25) -> 5 | AU25: =IF(M25=0,"",RANK(M25,$M$8:$M$474)) -> 39 | AV25: =IF(AB25=0,"",RANK(AB25,$AB$8:$AB$474)) -> 181 | AW25: =IF(OR(AU25="",AV25=""),"",AU25-AV25) -> -142
A26: HOMBRE | B26: CHAQUETA HOMBRE | C26: ABRIGO | D26: 2621JA62 | E26: =COUNTIF('Detalle por artículo'!$K$8:$K$592,D26) -> 1 | F26: =IFERROR(L26/G26,0) -> 142.42343 | G26: =SUMIF('Detalle por artículo'!$K$8:$K$592,$D26,'Detalle por artículo'!$E$8:$E$592) -> 22.464 | H26: =ROUNDUP(G26/1.54,0) -> 15 | I26: =ROUNDUP(G26/0.77,0) -> 30 | J26: =ROUNDUP(G26/0.385,0) -> 59 | K26: =G26/28 -> 0.80228571 | L26: =SUMIF('Detalle por artículo'!$K$8:$K$592,$D26,'Detalle por artículo'!$O$8:$O$592) -> 3199.4 | M26: =SUMIF('Detalle por artículo'!$K$8:$K$592,$D26,'Detalle por artículo'!$I$8:$I$592) -> 1803 | N26: =SUMIF('Detalle por artículo'!$K$8:$K$592,$D26,'Detalle por artículo'!$M$8:$M$592) -> 234 | O26: =IFERROR(G26/M26*1000,0) -> 12.459235 | P26: =IFERROR(L26/M26*1000,0) -> 1774.487 | Q26: =IF(F26=0,0,IF(F26<120,0.2,IF(F26>200,0.1,0.15))) -> 0.15 | R26: =G26*(1+Q26) -> 25.8336 | S26: =IFERROR(SUM($G$8:G26)/$G$6,0) -> 0.3541763 | T26: =IF(S26<=0.5,"A",IF(S26<=0.84,"B","C")) -> A | U26: 1803 | V26: =U26-M26 -> 0 | W26: 46223 | X26: 46223 | Y26: 0 | Z26: =Y26*O26/1000 -> 0 | AA26: =Z26/28 -> 0 | AB26: 464 | AC26: =IFERROR(INDEX(IMP_TOT,MATCH(D26,IMP_MOD,0)),0) -> 294 | AD26: =IFERROR(INDEX(REP_TOT,MATCH(D26,REP_MOD,0)),0) -> 143 | AE26: =IFERROR(INDEX(IMP_NT,MATCH(D26,IMP_MOD,0)),0) -> 37 | AF26: =IFERROR(AE26/TIENDAS,0) -> 0.74 | AG26: 5 | AH26: 22 | AI26: =IFERROR(AC26/M26,0) -> 0.16306156 | AJ26: =IFERROR(AD26/M26,0) -> 0.079312257 | AK26: =AC26*O26/1000 -> 3.663015 | AL26: 1339 | AM26: =AL26*O26/1000 -> 16.682915 | AN26: =IFERROR(AL26/U26,0) -> 0.74265114 | AO26: =M26-AB26 -> 1339 | AP26: =AO26*O26/1000 -> 16.682915 | AQ26: =IFERROR((AC26+AD26)/M26,0) -> 0.24237382 | AR26: 46233 | AS26: 46234 | AT26: =IF(OR(W26="",AS26=""),"",AS26-W26) -> 11 | AU26: =IF(M26=0,"",RANK(M26,$M$8:$M$474)) -> 56 | AV26: =IF(AB26=0,"",RANK(AB26,$AB$8:$AB$474)) -> 296 | AW26: =IF(OR(AU26="",AV26=""),"",AU26-AV26) -> -240
A27: HOMBRE | B27: CHAQUETA HOMBRE | C27: CAZADORA | D27: 2621JA44 | E27: =COUNTIF('Detalle por artículo'!$K$8:$K$592,D27) -> 1 | F27: =IFERROR(L27/G27,0) -> 126.51515 | G27: =SUMIF('Detalle por artículo'!$K$8:$K$592,$D27,'Detalle por artículo'!$E$8:$E$592) -> 20.46 | H27: =ROUNDUP(G27/1.54,0) -> 14 | I27: =ROUNDUP(G27/0.77,0) -> 27 | J27: =ROUNDUP(G27/0.385,0) -> 54 | K27: =G27/28 -> 0.73071429 | L27: =SUMIF('Detalle por artículo'!$K$8:$K$592,$D27,'Detalle por artículo'!$O$8:$O$592) -> 2588.5 | M27: =SUMIF('Detalle por artículo'!$K$8:$K$592,$D27,'Detalle por artículo'!$I$8:$I$592) -> 2546 | N27: =SUMIF('Detalle por artículo'!$K$8:$K$592,$D27,'Detalle por artículo'!$M$8:$M$592) -> 196 | O27: =IFERROR(G27/M27*1000,0) -> 8.0361351 | P27: =IFERROR(L27/M27*1000,0) -> 1016.6929 | Q27: =IF(F27=0,0,IF(F27<120,0.2,IF(F27>200,0.1,0.15))) -> 0.15 | R27: =G27*(1+Q27) -> 23.529 | S27: =IFERROR(SUM($G$8:G27)/$G$6,0) -> 0.3616946 | T27: =IF(S27<=0.5,"A",IF(S27<=0.84,"B","C")) -> A | U27: 2546 | V27: =U27-M27 -> 0 | W27: 46303 | X27: 46303 | Y27: 0 | Z27: =Y27*O27/1000 -> 0 | AA27: =Z27/28 -> 0 | AB27: 766 | AC27: =IFERROR(INDEX(IMP_TOT,MATCH(D27,IMP_MOD,0)),0) -> 423 | AD27: =IFERROR(INDEX(REP_TOT,MATCH(D27,REP_MOD,0)),0) -> 342 | AE27: =IFERROR(INDEX(IMP_NT,MATCH(D27,IMP_MOD,0)),0) -> 48 | AF27: =IFERROR(AE27/TIENDAS,0) -> 0.96 | AG27: 1 | AH27: 0 | AI27: =IFERROR(AC27/M27,0) -> 0.16614297 | AJ27: =IFERROR(AD27/M27,0) -> 0.13432836 | AK27: =AC27*O27/1000 -> 3.3992852 | AL27: 1780 | AM27: =AL27*O27/1000 -> 14.304321 | AN27: =IFERROR(AL27/U27,0) -> 0.6991359 | AO27: =M27-AB27 -> 1780 | AP27: =AO27*O27/1000 -> 14.304321 | AQ27: =IFERROR((AC27+AD27)/M27,0) -> 0.30047133 | AR27: 46303 | AS27: 46304 | AT27: =IF(OR(W27="",AS27=""),"",AS27-W27) -> 1 | AU27: =IF(M27=0,"",RANK(M27,$M$8:$M$474)) -> 27 | AV27: =IF(AB27=0,"",RANK(AB27,$AB$8:$AB$474)) -> 102 | AW27: =IF(OR(AU27="",AV27=""),"",AU27-AV27) -> -75
A28: MUJER | B28: CHAQUETA MUJER | C28: CAZADORA | D28: 2622JA12 | E28: =COUNTIF('Detalle por artículo'!$K$8:$K$592,D28) -> 2 | F28: =IFERROR(L28/G28,0) -> 230.40794 | G28: =SUMIF('Detalle por artículo'!$K$8:$K$592,$D28,'Detalle por artículo'!$E$8:$E$592) -> 18.949 | H28: =ROUNDUP(G28/1.54,0) -> 13 | I28: =ROUNDUP(G28/0.77,0) -> 25 | J28: =ROUNDUP(G28/0.385,0) -> 50 | K28: =G28/28 -> 0.67675 | L28: =SUMIF('Detalle por artículo'!$K$8:$K$592,$D28,'Detalle por artículo'!$O$8:$O$592) -> 4366 | M28: =SUMIF('Detalle por artículo'!$K$8:$K$592,$D28,'Detalle por artículo'!$I$8:$I$592) -> 3856 | N28: =SUMIF('Detalle por artículo'!$K$8:$K$592,$D28,'Detalle por artículo'!$M$8:$M$592) -> 242 | O28: =IFERROR(G28/M28*1000,0) -> 4.9141598 | P28: =IFERROR(L28/M28*1000,0) -> 1132.2614 | Q28: =IF(F28=0,0,IF(F28<120,0.2,IF(F28>200,0.1,0.15))) -> 0.1 | R28: =G28*(1+Q28) -> 20.8439 | S28: =IFERROR(SUM($G$8:G28)/$G$6,0) -> 0.36865768 | T28: =IF(S28<=0.5,"A",IF(S28<=0.84,"B","C")) -> A | U28: 3859 | V28: =U28-M28 -> 3 | W28: 46245 | X28: 46245 | Y28: 1 | Z28: =Y28*O28/1000 -> 0.0049141598 | AA28: =Z28/28 -> 0.00017550571 | AB28: 1652 | AC28: =IFERROR(INDEX(IMP_TOT,MATCH(D28,IMP_MOD,0)),0) -> 929 | AD28: =IFERROR(INDEX(REP_TOT,MATCH(D28,REP_MOD,0)),0) -> 696 | AE28: =IFERROR(INDEX(IMP_NT,MATCH(D28,IMP_MOD,0)),0) -> 48 | AF28: =IFERROR(AE28/TIENDAS,0) -> 0.96 | AG28: 11 | AH28: 16 | AI28: =IFERROR(AC28/M28,0) -> 0.24092324 | AJ28: =IFERROR(AD28/M28,0) -> 0.18049793 | AK28: =AC28*O28/1000 -> 4.5652544 | AL28: 2185 | AM28: =AL28*O28/1000 -> 10.737439 | AN28: =IFERROR(AL28/U28,0) -> 0.56620886 | AO28: =M28-AB28 -> 2204 | AP28: =AO28*O28/1000 -> 10.830808 | AQ28: =IFERROR((AC28+AD28)/M28,0) -> 0.42142116 | AR28: 46254 | AS28: 46255 | AT28: =IF(OR(W28="",AS28=""),"",AS28-W28) -> 10 | AU28: =IF(M28=0,"",RANK(M28,$M$8:$M$474)) -> 16 | AV28: =IF(AB28=0,"",RANK(AB28,$AB$8:$AB$474)) -> 17 | AW28: =IF(OR(AU28="",AV28=""),"",AU28-AV28) -> -1
A29: HOMBRE | B29: SUDADERA HOMBRE | C29: HIGH NECK | D29: 2621SU17 | E29: =COUNTIF('Detalle por artículo'!$K$8:$K$592,D29) -> 2 | F29: =IFERROR(L29/G29,0) -> 101.02508 | G29: =SUMIF('Detalle por artículo'!$K$8:$K$592,$D29,'Detalle por artículo'!$E$8:$E$592) -> 18.34 | H29: =ROUNDUP(G29/1.54,0) -> 12 | I29: =ROUNDUP(G29/0.77,0) -> 24 | J29: =ROUNDUP(G29/0.385,0) -> 48 | K29: =G29/28 -> 0.655 | L29: =SUMIF('Detalle por artículo'!$K$8:$K$592,$D29,'Detalle por artículo'!$O$8:$O$592) -> 1852.8 | M29: =SUMIF('Detalle por artículo'!$K$8:$K$592,$D29,'Detalle por artículo'!$I$8:$I$592) -> 3316 | N29: =SUMIF('Detalle por artículo'!$K$8:$K$592,$D29,'Detalle por artículo'!$M$8:$M$592) -> 191 | O29: =IFERROR(G29/M29*1000,0) -> 5.53076 | P29: =IFERROR(L29/M29*1000,0) -> 558.74548 | Q29: =IF(F29=0,0,IF(F29<120,0.2,IF(F29>200,0.1,0.15))) -> 0.2 | R29: =G29*(1+Q29) -> 22.008 | S29: =IFERROR(SUM($G$8:G29)/$G$6,0) -> 0.37539696 | T29: =IF(S29<=0.5,"A",IF(S29<=0.84,"B","C")) -> A | U29: 3313 | V29: =U29-M29 -> -3 | W29: 46234 | X29: 46234 | Y29: 19 | Z29: =Y29*O29/1000 -> 0.10508444 | AA29: =Z29/28 -> 0.0037530157 | AB29: 1474 | AC29: =IFERROR(INDEX(IMP_TOT,MATCH(D29,IMP_MOD,0)),0) -> 607 | AD29: =IFERROR(INDEX(REP_TOT,MATCH(D29,REP_MOD,0)),0) -> 823 | AE29: =IFERROR(INDEX(IMP_NT,MATCH(D29,IMP_MOD,0)),0) -> 44 | AF29: =IFERROR(AE29/TIENDAS,0) -> 0.88 | AG29: 10 | AH29: 38 | AI29: =IFERROR(AC29/M29,0) -> 0.18305187 | AJ29: =IFERROR(AD29/M29,0) -> 0.24819059 | AK29: =AC29*O29/1000 -> 3.3571713 | AL29: 1839 | AM29: =AL29*O29/1000 -> 10.171068 | AN29: =IFERROR(AL29/U29,0) -> 0.55508602 | AO29: =M29-AB29 -> 1842 | AP29: =AO29*O29/1000 -> 10.18766 | AQ29: =IFERROR((AC29+AD29)/M29,0) -> 0.43124246 | AR29: 46254 | AS29: 46255 | AT29: =IF(OR(W29="",AS29=""),"",AS29-W29) -> 21 | AU29: =IF(M29=0,"",RANK(M29,$M$8:$M$474)) -> 20 | AV29: =IF(AB29=0,"",RANK(AB29,$AB$8:$AB$474)) -> 24 | AW29: =IF(OR(AU29="",AV29=""),"",AU29-AV29) -> -4
A30: HOMBRE | B30: CHAQUETA HOMBRE | C30: SUDADERA | D30: 2621JA95 | E30: =COUNTIF('Detalle por artículo'!$K$8:$K$592,D30) -> 1 | F30: =IFERROR(L30/G30,0) -> 114.52736 | G30: =SUMIF('Detalle por artículo'!$K$8:$K$592,$D30,'Detalle por artículo'!$E$8:$E$592) -> 18.09 | H30: =ROUNDUP(G30/1.54,0) -> 12 | I30: =ROUNDUP(G30/0.77,0) -> 24 | J30: =ROUNDUP(G30/0.385,0) -> 47 | K30: =G30/28 -> 0.64607143 | L30: =SUMIF('Detalle por artículo'!$K$8:$K$592,$D30,'Detalle por artículo'!$O$8:$O$592) -> 2071.8 | M30: =SUMIF('Detalle por artículo'!$K$8:$K$592,$D30,'Detalle por artículo'!$I$8:$I$592) -> 2014 | N30: =SUMIF('Detalle por artículo'!$K$8:$K$592,$D30,'Detalle por artículo'!$M$8:$M$592) -> 201 | O30: =IFERROR(G30/M30*1000,0) -> 8.9821251 | P30: =IFERROR(L30/M30*1000,0) -> 1028.6991 | Q30: =IF(F30=0,0,IF(F30<120,0.2,IF(F30>200,0.1,0.15))) -> 0.2 | R30: =G30*(1+Q30) -> 21.708 | S30: =IFERROR(SUM($G$8:G30)/$G$6,0) -> 0.38204438 | T30: =IF(S30<=0.5,"A",IF(S30<=0.84,"B","C")) -> A | U30: 2018 | V30: =U30-M30 -> 4 | W30: 46259 | X30: 46259 | Y30: 6 | Z30: =Y30*O30/1000 -> 0.053892751 | AA30: =Z30/28 -> 0.0019247411 | AB30: 1326 | AC30: =IFERROR(INDEX(IMP_TOT,MATCH(D30,IMP_MOD,0)),0) -> 826 | AD30: =IFERROR(INDEX(REP_TOT,MATCH(D30,REP_MOD,0)),0) -> 471 | AE30: =IFERROR(INDEX(IMP_NT,MATCH(D30,IMP_MOD,0)),0) -> 48 | AF30: =IFERROR(AE30/TIENDAS,0) -> 0.96 | AG30: 13 | AH30: 16 | AI30: =IFERROR(AC30/M30,0) -> 0.4101291 | AJ30: =IFERROR(AD30/M30,0) -> 0.23386296 | AK30: =AC30*O30/1000 -> 7.4192354 | AL30: 690 | AM30: =AL30*O30/1000 -> 6.1976663 | AN30: =IFERROR(AL30/U30,0) -> 0.3419227 | AO30: =M30-AB30 -> 688 | AP30: =AO30*O30/1000 -> 6.1797021 | AQ30: =IFERROR((AC30+AD30)/M30,0) -> 0.64399206 | AR30: 46268 | AS30: 46268 | AT30: =IF(OR(W30="",AS30=""),"",AS30-W30) -> 9 | AU30: =IF(M30=0,"",RANK(M30,$M$8:$M$474)) -> 42 | AV30: =IF(AB30=0,"",RANK(AB30,$AB$8:$AB$474)) -> 37 | AW30: =IF(OR(AU30="",AV30=""),"",AU30-AV30) -> 5
A31: HOMBRE | B31: CHAQUETA HOMBRE | C31: ABRIGO | D31: 2621JA63 | E31: =COUNTIF('Detalle por artículo'!$K$8:$K$592,D31) -> 1 | F31: =IFERROR(L31/G31,0) -> 136.97917 | G31: =SUMIF('Detalle por artículo'!$K$8:$K$592,$D31,'Detalle por artículo'!$E$8:$E$592) -> 17.856 | H31: =ROUNDUP(G31/1.54,0) -> 12 | I31: =ROUNDUP(G31/0.77,0) -> 24 | J31: =ROUNDUP(G31/0.385,0) -> 47 | K31: =G31/28 -> 0.63771429 | L31: =SUMIF('Detalle por artículo'!$K$8:$K$592,$D31,'Detalle por artículo'!$O$8:$O$592) -> 2445.9 | M31: =SUMIF('Detalle por artículo'!$K$8:$K$592,$D31,'Detalle por artículo'!$I$8:$I$592) -> 1601 | N31: =SUMIF('Detalle por artículo'!$K$8:$K$592,$D31,'Detalle por artículo'!$M$8:$M$592) -> 186 | O31: =IFERROR(G31/M31*1000,0) -> 11.153029 | P31: =IFERROR(L31/M31*1000,0) -> 1527.7327 | Q31: =IF(F31=0,0,IF(F31<120,0.2,IF(F31>200,0.1,0.15))) -> 0.15 | R31: =G31*(1+Q31) -> 20.5344 | S31: =IFERROR(SUM($G$8:G31)/$G$6,0) -> 0.38860582 | T31: =IF(S31<=0.5,"A",IF(S31<=0.84,"B","C")) -> A | U31: 1601 | V31: =U31-M31 -> 0 | W31: 46223 | X31: 46223 | Y31: 0 | Z31: =Y31*O31/1000 -> 0 | AA31: =Z31/28 -> 0 | AB31: 400 | AC31: =IFERROR(INDEX(IMP_TOT,MATCH(D31,IMP_MOD,0)),0) -> 281 | AD31: =IFERROR(INDEX(REP_TOT,MATCH(D31,REP_MOD,0)),0) -> 90 | AE31: =IFERROR(INDEX(IMP_NT,MATCH(D31,IMP_MOD,0)),0) -> 35 | AF31: =IFERROR(AE31/TIENDAS,0) -> 0.7 | AG31: 7 | AH31: 22 | AI31: =IFERROR(AC31/M31,0) -> 0.1755153 | AJ31: =IFERROR(AD31/M31,0) -> 0.056214866 | AK31: =AC31*O31/1000 -> 3.1340012 | AL31: 1201 | AM31: =AL31*O31/1000 -> 13.394788 | AN31: =IFERROR(AL31/U31,0) -> 0.75015615 | AO31: =M31-AB31 -> 1201 | AP31: =AO31*O31/1000 -> 13.394788 | AQ31: =IFERROR((AC31+AD31)/M31,0) -> 0.23173017 | AR31: 46233 | AS31: 46234 | AT31: =IF(OR(W31="",AS31=""),"",AS31-W31) -> 11 | AU31: =IF(M31=0,"",RANK(M31,$M$8:$M$474)) -> 80 | AV31: =IF(AB31=0,"",RANK(AB31,$AB$8:$AB$474)) -> 323 | AW31: =IF(OR(AU31="",AV31=""),"",AU31-AV31) -> -243
A32: HOMBRE | B32: CHAQUETA HOMBRE | C32: CAZADORA | D32: 2621JA23 | E32: =COUNTIF('Detalle por artículo'!$K$8:$K$592,D32) -> 1 | F32: =IFERROR(L32/G32,0) -> 139.89217 | G32: =SUMIF('Detalle por artículo'!$K$8:$K$592,$D32,'Detalle por artículo'!$E$8:$E$592) -> 17.62 | H32: =ROUNDUP(G32/1.54,0) -> 12 | I32: =ROUNDUP(G32/0.77,0) -> 23 | J32: =ROUNDUP(G32/0.385,0) -> 46 | K32: =G32/28 -> 0.62928571 | L32: =SUMIF('Detalle por artículo'!$K$8:$K$592,$D32,'Detalle por artículo'!$O$8:$O$592) -> 2464.9 | M32: =SUMIF('Detalle por artículo'!$K$8:$K$592,$D32,'Detalle por artículo'!$I$8:$I$592) -> 1608 | N32: =SUMIF('Detalle por artículo'!$K$8:$K$592,$D32,'Detalle por artículo'!$M$8:$M$592) -> 161 | O32: =IFERROR(G32/M32*1000,0) -> 10.957711 | P32: =IFERROR(L32/M32*1000,0) -> 1532.898 | Q32: =IF(F32=0,0,IF(F32<120,0.2,IF(F32>200,0.1,0.15))) -> 0.15 | R32: =G32*(1+Q32) -> 20.263 | S32: =IFERROR(SUM($G$8:G32)/$G$6,0) -> 0.39508053 | T32: =IF(S32<=0.5,"A",IF(S32<=0.84,"B","C")) -> A | U32: 1613 | V32: =U32-M32 -> 5 | W32: 46272 | X32: 46272 | Y32: 1618 | Z32: =Y32*O32/1000 -> 17.729577 | AA32: =Z32/28 -> 0.63319918 | AB32: 842 | AC32: =IFERROR(INDEX(IMP_TOT,MATCH(D32,IMP_MOD,0)),0) -> 576 | AD32: =IFERROR(INDEX(REP_TOT,MATCH(D32,REP_MOD,0)),0) -> 251 | AE32: =IFERROR(INDEX(IMP_NT,MATCH(D32,IMP_MOD,0)),0) -> 48 | AF32: =IFERROR(AE32/TIENDAS,0) -> 0.96 | AG32: 6 | AH32: 9 | AI32: =IFERROR(AC32/M32,0) -> 0.35820896 | AJ32: =IFERROR(AD32/M32,0) -> 0.15609453 | AK32: =AC32*O32/1000 -> 6.3116418 | AL32: 788 | AM32: =AL32*O32/1000 -> 8.6346766 | AN32: =IFERROR(AL32/U32,0) -> 0.48853069 | AO32: =M32-AB32 -> 766 | AP32: =AO32*O32/1000 -> 8.393607 | AQ32: =IFERROR((AC32+AD32)/M32,0) -> 0.51430348 | AR32: 46274 | AS32: 46275 | AT32: =IF(OR(W32="",AS32=""),"",AS32-W32) -> 3 | AU32: =IF(M32=0,"",RANK(M32,$M$8:$M$474)) -> 77 | AV32: =IF(AB32=0,"",RANK(AB32,$AB$8:$AB$474)) -> 89 | AW32: =IF(OR(AU32="",AV32=""),"",AU32-AV32) -> -12
... A42: HOMBRE | B42: CHAQUETA HOMBRE | C42: SUDADERA | D42: 2621JA84 | E42: =COUNTIF('Detalle por artículo'!$K$8:$K$592,D42) -> 1 | F42: =IFERROR(L42/G42,0) -> 120 | G42: =SUMIF('Detalle por artículo'!$K$8:$K$592,$D42,'Detalle por artículo'!$E$8:$E$592) -> 14.58 | H42: =ROUNDUP(G42/1.54,0) -> 10 | I42: =ROUNDUP(G42/0.77,0) -> 19 | J42: =ROUNDUP(G42/0.385,0) -> 38 | K42: =G42/28 -> 0.52071429 | L42: =SUMIF('Detalle por artículo'!$K$8:$K$592,$D42,'Detalle por artículo'!$O$8:$O$592) -> 1749.6 | M42: =SUMIF('Detalle por artículo'!$K$8:$K$592,$D42,'Detalle por artículo'!$I$8:$I$592) -> 1619 | N42: =SUMIF('Detalle por artículo'!$K$8:$K$592,$D42,'Detalle por artículo'!$M$8:$M$592) -> 162 | O42: =IFERROR(G42/M42*1000,0) -> 9.005559 | P42: =IFERROR(L42/M42*1000,0) -> 1080.6671 | Q42: =IF(F42=0,0,IF(F42<120,0.2,IF(F42>200,0.1,0.15))) -> 0.15 | R42: =G42*(1+Q42) -> 16.767 | S42: =IFERROR(SUM($G$8:G42)/$G$6,0) -> 0.4526283 | T42: =IF(S42<=0.5,"A",IF(S42<=0.84,"B","C")) -> A | U42: 1620 | V42: =U42-M42 -> 1 | W42: 46259 | X42: 46259 | Y42: 0 | Z42: =Y42*O42/1000 -> 0 | AA42: =Z42/28 -> 0 | AB42: 969 | AC42: =IFERROR(INDEX(IMP_TOT,MATCH(D42,IMP_MOD,0)),0) -> 459 | AD42: =IFERROR(INDEX(REP_TOT,MATCH(D42,REP_MOD,0)),0) -> 496 | AE42: =IFERROR(INDEX(IMP_NT,MATCH(D42,IMP_MOD,0)),0) -> 47 | AF42: =IFERROR(AE42/TIENDAS,0) -> 0.94 | AG42: 5 | AH42: 9 | AI42: =IFERROR(AC42/M42,0) -> 0.28350834 | AJ42: =IFERROR(AD42/M42,0) -> 0.30636195 | AK42: =AC42*O42/1000 -> 4.1335516 | AL42: 651 | AM42: =AL42*O42/1000 -> 5.8626189 | AN42: =IFERROR(AL42/U42,0) -> 0.40185185 | AO42: =M42-AB42 -> 650 | AP42: =AO42*O42/1000 -> 5.8536133 | AQ42: =IFERROR((AC42+AD42)/M42,0) -> 0.58987029 | AR42: 46268 | AS42: 46268 | AT42: =IF(OR(W42="",AS42=""),"",AS42-W42) -> 9 | AU42: =IF(M42=0,"",RANK(M42,$M$8:$M$474)) -> 76 | AV42: =IF(AB42=0,"",RANK(AB42,$AB$8:$AB$474)) -> 70 | AW42: =IF(OR(AU42="",AV42=""),"",AU42-AV42) -> 6
A43: HOMBRE | B43: CHAQUETA HOMBRE | C43: PLUMIFERO | D43: 2621JA65 | E43: =COUNTIF('Detalle por artículo'!$K$8:$K$592,D43) -> 1 | F43: =IFERROR(L43/G43,0) -> 102.92493 | G43: =SUMIF('Detalle por artículo'!$K$8:$K$592,$D43,'Detalle por artículo'!$E$8:$E$592) -> 14.12 | H43: =ROUNDUP(G43/1.54,0) -> 10 | I43: =ROUNDUP(G43/0.77,0) -> 19 | J43: =ROUNDUP(G43/0.385,0) -> 37 | K43: =G43/28 -> 0.50428571 | L43: =SUMIF('Detalle por artículo'!$K$8:$K$592,$D43,'Detalle por artículo'!$O$8:$O$592) -> 1453.3 | M43: =SUMIF('Detalle por artículo'!$K$8:$K$592,$D43,'Detalle por artículo'!$I$8:$I$592) -> 1027 | N43: =SUMIF('Detalle por artículo'!$K$8:$K$592,$D43,'Detalle por artículo'!$M$8:$M$592) -> 129 | O43: =IFERROR(G43/M43*1000,0) -> 13.748783 | P43: =IFERROR(L43/M43*1000,0) -> 1415.0925 | Q43: =IF(F43=0,0,IF(F43<120,0.2,IF(F43>200,0.1,0.15))) -> 0.2 | R43: =G43*(1+Q43) -> 16.944 | S43: =IFERROR(SUM($G$8:G43)/$G$6,0) -> 0.45781688 | T43: =IF(S43<=0.5,"A",IF(S43<=0.84,"B","C")) -> A | U43: 1026 | V43: =U43-M43 -> -1 | W43: 46308 | X43: 46308 | Y43: 11 | Z43: =Y43*O43/1000 -> 0.15123661 | AA43: =Z43/28 -> 0.0054013076 | AB43: 0 | AC43: =IFERROR(INDEX(IMP_TOT,MATCH(D43,IMP_MOD,0)),0) -> 0 | AD43: =IFERROR(INDEX(REP_TOT,MATCH(D43,REP_MOD,0)),0) -> 0 | AE43: =IFERROR(INDEX(IMP_NT,MATCH(D43,IMP_MOD,0)),0) -> 0 | AF43: =IFERROR(AE43/TIENDAS,0) -> 0 | AG43: 0 | AH43: 0 | AI43: =IFERROR(AC43/M43,0) -> 0 | AJ43: =IFERROR(AD43/M43,0) -> 0 | AK43: =AC43*O43/1000 -> 0 | AL43: 1026 | AM43: =AL43*O43/1000 -> 14.106251 | AN43: =IFERROR(AL43/U43,0) -> 1 | AO43: =M43-AB43 -> 1027 | AP43: =AO43*O43/1000 -> 14.12 | AQ43: =IFERROR((AC43+AD43)/M43,0) -> 0 | AT43: =IF(OR(W43="",AS43=""),"",AS43-W43) | AU43: =IF(M43=0,"",RANK(M43,$M$8:$M$474)) -> 167 | AV43: =IF(AB43=0,"",RANK(AB43,$AB$8:$AB$474)) | AW43: =IF(OR(AU43="",AV43=""),"",AU43-AV43)
A44: HOMBRE | B44: TRICOT HOMBRE | C44: JERSEY HIGH NECK | D44: 2621TR17 | E44: =COUNTIF('Detalle por artículo'!$K$8:$K$592,D44) -> 1 | F44: =IFERROR(L44/G44,0) -> 150.84635 | G44: =SUMIF('Detalle por artículo'!$K$8:$K$592,$D44,'Detalle por artículo'!$E$8:$E$592) -> 13.824 | H44: =ROUNDUP(G44/1.54,0) -> 9 | I44: =ROUNDUP(G44/0.77,0) -> 18 | J44: =ROUNDUP(G44/0.385,0) -> 36 | K44: =G44/28 -> 0.49371429 | L44: =SUMIF('Detalle por artículo'!$K$8:$K$592,$D44,'Detalle por artículo'!$O$8:$O$592) -> 2085.3 | M44: =SUMIF('Detalle por artículo'!$K$8:$K$592,$D44,'Detalle por artículo'!$I$8:$I$592) -> 3146 | N44: =SUMIF('Detalle por artículo'!$K$8:$K$592,$D44,'Detalle por artículo'!$M$8:$M$592) -> 144 | O44: =IFERROR(G44/M44*1000,0) -> 4.3941513 | P44: =IFERROR(L44/M44*1000,0) -> 662.8417 | Q44: =IF(F44=0,0,IF(F44<120,0.2,IF(F44>200,0.1,0.15))) -> 0.15 | R44: =G44*(1+Q44) -> 15.8976 | S44: =IFERROR(SUM($G$8:G44)/$G$6,0) -> 0.4628967 | T44: =IF(S44<=0.5,"A",IF(S44<=0.84,"B","C")) -> A | U44: 3160 | V44: =U44-M44 -> 14 | W44: 46275 | X44: 46289 | Y44: 48 | Z44: =Y44*O44/1000 -> 0.21091926 | AA44: =Z44/28 -> 0.0075328308 | AB44: 555 | AC44: =IFERROR(INDEX(IMP_TOT,MATCH(D44,IMP_MOD,0)),0) -> 511 | AD44: =IFERROR(INDEX(REP_TOT,MATCH(D44,REP_MOD,0)),0) -> 20 | AE44: =IFERROR(INDEX(IMP_NT,MATCH(D44,IMP_MOD,0)),0) -> 41 | AF44: =IFERROR(AE44/TIENDAS,0) -> 0.82 | AG44: 3 | AH44: 21 | AI44: =IFERROR(AC44/M44,0) -> 0.16242848 | AJ44: =IFERROR(AD44/M44,0) -> 0.0063572791 | AK44: =AC44*O44/1000 -> 2.2454113 | AL44: 2604 | AM44: =AL44*O44/1000 -> 11.44237 | AN44: =IFERROR(AL44/U44,0) -> 0.82405063 | AO44: =M44-AB44 -> 2591 | AP44: =AO44*O44/1000 -> 11.385246 | AQ44: =IFERROR((AC44+AD44)/M44,0) -> 0.16878576 | AR44: 46281 | AS44: 46283 | AT44: =IF(OR(W44="",AS44=""),"",AS44-W44) -> 8 | AU44: =IF(M44=0,"",RANK(M44,$M$8:$M$474)) -> 22 | AV44: =IF(AB44=0,"",RANK(AB44,$AB$8:$AB$474)) -> 234 | AW44: =IF(OR(AU44="",AV44=""),"",AU44-AV44) -> -212
A45: HOMBRE | B45: TRICOT HOMBRE | C45: JERSEY | D45: 2621TR24 | E45: =COUNTIF('Detalle por artículo'!$K$8:$K$592,D45) -> 1 | F45: =IFERROR(L45/G45,0) -> 171.23843 | G45: =SUMIF('Detalle por artículo'!$K$8:$K$592,$D45,'Detalle por artículo'!$E$8:$E$592) -> 13.824 | H45: =ROUNDUP(G45/1.54,0) -> 9 | I45: =ROUNDUP(G45/0.77,0) -> 18 | J45: =ROUNDUP(G45/0.385,0) -> 36 | K45: =G45/28 -> 0.49371429 | L45: =SUMIF('Detalle por artículo'!$K$8:$K$592,$D45,'Detalle por artículo'!$O$8:$O$592) -> 2367.2 | M45: =SUMIF('Detalle por artículo'!$K$8:$K$592,$D45,'Detalle por artículo'!$I$8:$I$592) -> 4573 | N45: =SUMIF('Detalle por artículo'!$K$8:$K$592,$D45,'Detalle por artículo'!$M$8:$M$592) -> 144 | O45: =IFERROR(G45/M45*1000,0) -> 3.0229609 | P45: =IFERROR(L45/M45*1000,0) -> 517.64706 | Q45: =IF(F45=0,0,IF(F45<120,0.2,IF(F45>200,0.1,0.15))) -> 0.15 | R45: =G45*(1+Q45) -> 15.8976 | S45: =IFERROR(SUM($G$8:G45)/$G$6,0) -> 0.46797652 | T45: =IF(S45<=0.5,"A",IF(S45<=0.84,"B","C")) -> A | U45: 4596 | V45: =U45-M45 -> 23 | W45: 46275 | X45: 46289 | Y45: 13 | Z45: =Y45*O45/1000 -> 0.039298491 | AA45: =Z45/28 -> 0.0014035175 | AB45: 2157 | AC45: =IFERROR(INDEX(IMP_TOT,MATCH(D45,IMP_MOD,0)),0) -> 1420 | AD45: =IFERROR(INDEX(REP_TOT,MATCH(D45,REP_MOD,0)),0) -> 709 | AE45: =IFERROR(INDEX(IMP_NT,MATCH(D45,IMP_MOD,0)),0) -> 47 | AF45: =IFERROR(AE45/TIENDAS,0) -> 0.94 | AG45: 11 | AH45: 28 | AI45: =IFERROR(AC45/M45,0) -> 0.31051826 | AJ45: =IFERROR(AD45/M45,0) -> 0.15504045 | AK45: =AC45*O45/1000 -> 4.2926044 | AL45: 2460 | AM45: =AL45*O45/1000 -> 7.4364837 | AN45: =IFERROR(AL45/U45,0) -> 0.53524804 | AO45: =M45-AB45 -> 2416 | AP45: =AO45*O45/1000 -> 7.3034734 | AQ45: =IFERROR((AC45+AD45)/M45,0) -> 0.46555871 | AR45: 46281 | AS45: 46282 | AT45: =IF(OR(W45="",AS45=""),"",AS45-W45) -> 7 | AU45: =IF(M45=0,"",RANK(M45,$M$8:$M$474)) -> 12 | AV45: =IF(AB45=0,"",RANK(AB45,$AB$8:$AB$474)) -> 7 | AW45: =IF(OR(AU45="",AV45=""),"",AU45-AV45) -> 5
